Workbook

Sheet All Responses
A1: Submission Timestamp | B1: Email Address | C1: Workflow Status | D1: Post-Processing Status | E1: Have all Recruiting Requirements been met? | F1: Date Requested | G1: Requester Name | H1: Requester Email | I1: Hire Date | J1: New Hire or Rehire | K1: Employee Type | L1: Hourly or Salary | M1: Temporary ID | N1: First Name | O1: Middle Name | P1: Last Name | Q1: Preferred Name | R1: Position / Job Title | S1: Site Name | T1: Job Site Number | U1: Reporting Manager Name | V1: Reporting Manager Email | W1: E-Business Card | X1: 30-60-90 | Y1: ADP Manager Access | Z1: Cost Sheet | AA1: Leader Access | AB1: Trip Reports Access | AC1: JR | AD1: JONAS Purchasing Software | AE1: JONAS Field Time/Field Project Access | AF1: JONAS EBI Access | AG1: Incidents | AH1: SiteDocs Training Login | AI1: CAA | AJ1: Transform | AK1: Net Promoter Score | AL1: Fleetio / Vehicle | AM1: Credit Card | AN1: Google Account | AO1: Delivery App | AP1: Mobile Phone | AQ1: Computer | AR1: SiteDocs Tablet | AS1: Is the new User getting a previous user assigned computer? | AT1: Reassigned Computer - Previous User's Name | AU1: Is the new User getting a previous user assigned phone? | AV1: Reassigned Phone - Previous User's Name | AW1: Phone Number | AX1: Cost Sheet - Job Site(s) to be assigned | AY1: Delivery Module - Job Site(s) to be assigned | AZ1: JONAS Purchasing - Job Number(s) to be assigned | BA1: JONAS Field Time/Field Project - Job Number(s) to be Assigned | BB1: JONAS EBI - Job Number(s) to be Assigned | BC1: Vehicle Assigned | BD1: Fleetio Access Required | BE1: Additional Notes/Comments | BF1: Signer Name | BG1: Request Date | BH1: BOSS User Account | BI1: Additional System/Equipment Access Needed? | BJ1: Email Requested | BK1: Date Required By | BL1: SiteDocs | BM1: ADP Supervisor Access | BN1: Additional Credit/ Purchasing Accounts | BO1: Request ID | BP1: HR - Email Address Requested | BQ1: HR - SiteDocs Worker ID | BR1: HR - DSS Username | BS1: HR - DSS Password | BT1: HR - Employee assigned to WIS module? | BU1: HR - SiteDocs Training Username | BV1: HR - SiteDocs Training Password | BW1: HR - Date of Submission | BX1: Final Status | BY1: Approval Notes | BZ1: IT - BOSS User Account | CA1: IT - Cost Sheet | CB1: IT - Leader Access | CC1: IT - Trip Reports Access | CD1: IT - Incidents | CE1: IT - CAA | CF1: IT - Transform | CG1: IT - Net Promoter Score | CH1: IT - E-Business Card | CI1: IT - Delivery App | CJ1: IT - Google Account Email | CK1: IT - Google Account Password | CL1: IT - Phone Number | CM1: IT - Phone Voicemail Password | CN1: IT - Computer Model | CO1: IT - Computer Serial Number | CP1: IT - Completion Timestamp | CQ1: Fleetio - Status | CR1: Fleetio - Asset Number | CS1: Fleetio - Vehicle Make | CT1: Fleetio - Vehicle Model | CU1: Fleetio - License Plate | CV1: Fleetio - Timestamp | CW1: Credit Card - Limit | CX1: Credit Card - Currency | CY1: Credit Card - Per | CZ1: Credit Card - Spend Dynamics Username | DA1: Credit Card - Spend Dynamics Password | DB1: Amazon - Username / Number | DC1: Amazon - Password / PIN | DD1: Staples - Username / Number | DE1: Staples - Password / PIN | DF1: HomeDepot - Card Number | DG1: HomeDepot - PIN | DH1: Credit Card - Status | DI1: Credit Card - Timestamp | DJ1: Business Card - Status | DK1: Business Card - Timestamp | DL1: 30-60-90 - Status | DM1: 30-60-90 - Timestamp | DN1: ADP Manager Access - Status | DO1: ADP Manager Access - Timestamp | DP1: ADP Supervisor Access | DQ1: ADP Supervisor Access - Status | DR1: ADP Supervisor Access - Timestamp | DS1: SiteDocs Tablet - Status | DT1: SiteDocs Tablet - Timestamp | DU1: SiteDocs - Status | DV1: SiteDocs - Timestamp | DW1: JR - Status | DX1: JR - Timestamp | DY1: JONAS - Status | DZ1: JONAS - Timestamp | EA1: Final Approver Name | EB1: Final Approval Comments | EC1: Final Denial Reason | ED1: Final Approval Timestamp
F2: 45863 | G2: z | H2: z | I2: 45856 | N2: z | O2: z | P2: z | Q2: z | R2: z | S2: z | T2: z | U2: z | V2: z | AT2: z | AV2: z | AW2: z | AX2: z | AY2: z | AZ2: z | BA2: z, z, z | BB2: z | BE2: z | BF2: z | BG2: 45863
F3: 45863 | G3: z | H3: Vishal.srikanth@team-group.com | I3: 45856 | N3: z | O3: z | P3: z | Q3: z | R3: z | S3: z | T3: z | U3: z | V3: z | AT3: z | AV3: z | AW3: z | AX3: z | AY3: z | AZ3: z | BA3: z, z, z | BB3: z | BE3: z | BF3: z | BG3: 45863
E4: Yes | F4: 45862 | G4: Vish | H4: Vishal.srikanth@team-group.com | I4: 45866 | J4: New Hire | K4: Direct Hire | L4: Hourly | N4: x | O4: y | P4: z | Q4: V | R4: ss | S4: sss | T4: 123 | U4: vs | V4: Vishal.srikanth@team-group.com | W4: Required | X4: Required | Y4: Required | Z4: Required | AA4: Required | AB4: Required | AC4: Required | AD4: Required | AE4: Required | AF4: Required | AG4: Required | AI4: Required | AJ4: Required | AK4: Required | AL4: Required | AM4: Required | AN4: Required | AO4: Required | AP4: Required | AQ4: Required | AR4: Required | AS4: Yes | AT4: vs | AU4: Yes | AV4: vs | AW4: 123 | AX4: vs, vs, vs, vs, vs | AY4: vs | AZ4: vs | BA4: vs, vs, vs, sv, vs, vs | BB4: vs | BC4: Yes | BD4: Yes | BE4: vs | BF4: Vish | BG4: 45862
E5: Yes | F5: 45863 | G5: Vish | H5: Vishal.srikanth@team-group.com | I5: 45902 | J5: New Hire | K5: Direct Hire | L5: Salary | N5: John | O5: JD | P5: Doe | Q5: JD | R5: VP | S5: Form Cambridge | T5: 123 | U5: VS | V5: Vishal.srikanth@team-group.com | W5: Required | X5: Required | Y5: Required | Z5: Required | AA5: Required | AB5: Required | AC5: Required | AD5: Required | AE5: Required | AF5: Required | AG5: Required | AI5: Required | AJ5: Required | AK5: Required | AL5: Required | AM5: Required | AN5: Required | AO5: Required | AP5: Required | AQ5: Required | AR5: Required | BE5: None | BF5: Vish | BG5: 45863
E6: Yes | F6: 45863 | G6: Vish | H6: Vishal.srikanth@team-group.com | I6: 45874 | J6: New Hire | K6: Direct Hire | L6: Salary | N6: John | O6: JD | P6: Doe | Q6: JD | R6: VP | S6: Form Cambridge | T6: 123 | U6: VS | V6: Vishal.srikanth@team-group.com | W6: Required | X6: Required | Y6: Required | Z6: Required | AA6: Required | AB6: Required | AC6: Required | AD6: Required | AE6: Required | AF6: Required | AG6: Required | AI6: Required | AJ6: Required | AK6: Required | AL6: Required | AM6: Required | AN6: Required | AO6: Required | AP6: Required | AQ6: Required | AR6: Required | BE6: none | BF6: Vish | BG6: 45863
E7: Yes | F7: 45863 | G7: Vish | H7: Vishal.srikanth@team-group.com | I7: 45874 | J7: New Hire | K7: Direct Hire | L7: Salary | M7: 250725006 | N7: John | O7: JD | P7: Doe | Q7: JD | R7: VP | S7: Form Cambridge | T7: 123 | U7: VS | V7: Vishal.srikanth@team-group.com | W7: Required | X7: Required | Y7: Required | Z7: Required | AA7: Required | AB7: Required | AC7: Required | AD7: Required | AE7: Required | AF7: Required | AG7: Required | AI7: Required | AJ7: Required | AK7: Required | AL7: Required | AM7: Required | AN7: Required | AO7: Required | AP7: Required | AQ7: Required | AR7: Required | BE7: none | BF7: Vish | BG7: 45863
E8: Yes | F8: 45863 | G8: Vish | H8: Vishal.srikanth@team-group.com | I8: 45874 | J8: New Hire | K8: Direct Hire | L8: Salary | M8: 250725007 | N8: John | O8: JD | P8: Doe | Q8: JD | R8: VP | S8: Form Cambridge | T8: 123 | U8: VS | V8: Vishal.srikanth@team-group.com | W8: Required | X8: Required | Y8: Required | Z8: Required | AA8: Required | AB8: Required | AC8: Required | AD8: Required | AE8: Required | AF8: Required | AG8: Required | AI8: Required | AJ8: Required | AK8: Required | AL8: Required | AM8: Required | AN8: Required | AO8: Required | AP8: Required | AQ8: Required | AR8: Required | AS8: Yes | AT8: vs | AU8: Yes | AV8: usnm | AW8: 123 | AX8: 123 | AY8: 123 | AZ8: 123, 123, 12 | BA8: 123 | BB8: 123 | BC8: Yes | BD8: Yes | BE8: none | BF8: Vish | BG8: 45863
E9: Yes | F9: 45865 | G9: Vish | H9: Vishal.srikanth@team-group.com | I9: 45874 | J9: New Hire | K9: Direct Hire | L9: Hourly | M9: 250727008 | N9: John | O9: JD | P9: Doe | Q9: JD | R9: VP | S9: Form Cambridge | T9: 123 | U9: VS | V9: Vishal.srikanth@team-group.com | W9: Required | X9: Required | Y9: Required | Z9: Required | AA9: Required | AB9: Required | AC9: Required | AD9: Required | AE9: Required | AF9: Required | AG9: Required | AI9: Required | AJ9: Required | AK9: Required | AL9: Required | AM9: Required | AN9: Required | AO9: Required | AP9: Required | AQ9: Required | AR9: Required | AS9: Yes | AT9: vs | AU9: Yes | AV9: usnm | AW9: 123 | AX9: 123, 123, 123 | AY9: 123, 123 | AZ9: 123 | BB9: 123 | BC9: No | BD9: Yes | BE9: none | BF9: Vish | BG9: 45865
E10: Yes | F10: 45865 | G10: Vish | H10: Vishal.srikanth@team-group.com | I10: 45874 | J10: New Hire | K10: Direct Hire | L10: Hourly | M10: 250727009 | N10: John | O10: JD | P10: Doe | Q10: JD | R10: VP | S10: Form Cambridge | T10: 123 | U10: VS | V10: Vishal.srikanth@team-group.com | W10: Required | X10: Required | Y10: Required | Z10: Required | AD10: Required | AE10: Not Required | BE10: none | BF10: Vish | BG10: 45865
E11: Yes | F11: 45866 | G11: Vish | H11: Vishal.srikanth@team-group.com | M11: 250727010 | N11: John | O11: JD | P11: Doe | Q11: JD | R11: VP | S11: Form Cambridge | T11: 123 | U11: VS | V11: Vishal.srikanth@team-group.com | AF11: Required | AP11: Required | AQ11: Required | AS11: Yes | AT11: vs | AU11: Yes | AV11: usnm | AW11: 123 | BB11: 123, 123 | BE11: none | BF11: Vish | BG11: 45866
E12: Yes | F12: 45865 | G12: Vish | H12: Vishal.srikanth@team-group.com | I12: 45874 | J12: New Hire | K12: Direct Hire | L12: Hourly | M12: 250727011 | N12: John | O12: JD | P12: Doe | Q12: JD | R12: VP | S12: Form Cambridge | T12: 123 | U12: VS | V12: Vishal.srikanth@team-group.com | W12: Required | AD12: Required | AO12: Required | AP12: Required | AQ12: Required | AS12: Yes | AT12: usnm | AU12: Yes | AV12: usnm | AW12: 123 | AY12: 123, 123, 123, 123 | AZ12: 123 | BE12: none | BF12: Vish | BG12: 45865
E13: Yes | F13: 45865 | G13: Vish | H13: Vishal.srikanth@team-group.com | I13: 45874 | J13: New Hire | K13: Direct Hire | L13: Hourly | M13: 250727012 | N13: John | O13: JD | P13: Doe | Q13: JD | R13: VP | S13: Form Cambridge | T13: 123 | U13: VS | V13: Vishal.srikanth@team-group.com | W13: Required | AD13: Required | AO13: Required | AP13: Required | AQ13: Required | AS13: Yes | AT13: usnm | AU13: Yes | AV13: usnm | AW13: 123 | AY13: 123, 123, 123, 123 | AZ13: 123 | BE13: none | BF13: Vish | BG13: 45865
E14: Yes | G14: Vish | H14: Vishal.srikanth@team-group.com | M14: 250727013 | N14: John | O14: JD | P14: Doe | Q14: JD | R14: VP | S14: Form Cambridge | T14: 123 | U14: VS | V14: Vishal.srikanth@team-group.com | AD14: Required | AZ14: 123 | BF14: Vish | BG14: 45866
E15: Yes | F15: 45866 | G15: Vish | H15: Vishal.srikanth@team-group.com | M15: 250727014 | N15: John | O15: JD | P15: Doe | Q15: JD | R15: VP | S15: Form Cambridge | T15: 123 | U15: VS | V15: Vishal.srikanth@team-group.com | AF15: Required | BB15: 123 | BF15: Vish | BG15: 45865
E16: Yes | F16: 45865 | G16: Vish | H16: Vishal.srikanth@team-group.com | I16: 45867 | J16: New Hire | K16: Direct Hire | L16: Hourly | M16: 250727015 | N16: John | O16: JD | P16: Doe | Q16: JD | AN16: Required | BF16: Vish | BG16: 45867
E17: Yes | F17: 45866 | G17: Vish | H17: Vishal.srikanth@team-group.com | I17: 45867 | J17: New Hire | K17: Direct Hire | L17: Hourly | M17: 250727016 | N17: John | O17: JD | P17: Doe | Q17: JD | R17: VP | S17: Form Cambridge | T17: 123 | U17: VS | V17: Vishal.srikanth@team-group.com | BF17: Vish | BG17: 45865
E18: Yes | G18: Vish | H18: Vishal.srikanth@team-group.com | J18: New Hire | K18: Direct Hire | L18: Hourly | M18: 250727017 | W18: Required | X18: Required | Y18: Required | Z18: Required | AA18: Required | AB18: Required | AC18: Required | AD18: Required | AE18: Required | AF18: Required | AG18: Required | AI18: Required | AJ18: Required | AK18: Required | AL18: Required | AM18: Required | AN18: Required | AO18: Required | AP18: Required | AQ18: Required | AR18: Required | AS18: Yes | AU18: Yes | BC18: Yes | BD18: Yes
E19: Yes | G19: Vish | H19: Vishal.srikanth@team-group.com | J19: New Hire | K19: Direct Hire | L19: Hourly | M19: 250728018 | W19: Required | X19: Required | Y19: Required | Z19: Required | AA19: Required | AB19: Required | AC19: Required | AD19: Required | AE19: Required | AF19: Required | AG19: Required | AI19: Required | AJ19: Required | AK19: Required | AL19: Required | AM19: Required | AN19: Required | AO19: Required | AP19: Required | AQ19: Required | AR19: Required | AS19: Yes | AU19: Yes | BC19: Yes | BD19: Yes | BF19: Vish | BG19: 45866
E20: Yes | F20: 45866 | G20: Vish | H20: Vishal.srikanth@team-group.com | I20: 45874 | J20: New Hire | K20: Direct Hire | L20: Hourly | M20: 250728019 | N20: John | O20: JD | P20: Doe | Q20: JD | R20: VP | S20: Form Cambridge | T20: 123 | U20: VS | V20: Vishal.srikanth@team-group.com | W20: Required | X20: Not Required | Y20: Required | Z20: Required | AA20: Not Required | AB20: Not Required | AC20: Required | AD20: Not Required | AE20: Not Required | AF20: Required | AL20: Required | AM20: Not Required | AN20: Not Required | AO20: Not Required | AP20: Required | AQ20: Required | AR20: Not Required | AS20: Yes | AT20: usnm | AU20: Yes | AV20: usnm | AW20: 123 | AX20: 123, 123 | BB20: 123, 123, 123, 123, 123 | BC20: Yes | BD20: Yes | BE20: none | BF20: Vish | BG20: 45866
E21: Yes | F21: 45866 | G21: Vish | H21: Vishal.srikanth@team-group.com | J21: New Hire | K21: Direct Hire | L21: Salary | M21: 250728020 | N21: John | O21: JD | P21: Doe | Q21: JD | R21: VP | S21: Form Cambridge | T21: 123 | U21: VS | V21: Vishal.srikanth@team-group.com | X21: Required | Y21: Required | AB21: Required | AF21: Required | AL21: Required | AN21: Required | BB21: 123, 123, 123 | BC21: Yes | BD21: Yes | BF21: Vish | BG21: 45866
E22: Yes | F22: 45866 | G22: Vish | H22: Vishal.srikanth@team-group.com | I22: 45866 | J22: New Hire | K22: Direct Hire | L22: Salary | M22: 250728021 | N22: John | O22: JD | P22: Doe | Q22: JD | R22: VP | S22: Form Cambridge | T22: 123 | U22: VS | V22: Vishal.srikanth@team-group.com | AB22: Required | AO22: Required | AY22: 123, 123, 123 | BF22: Vish | BG22: 45866 | BO22: REQ-1753710025359
E23: Yes | F23: 45866 | G23: Vish | H23: Vishal.srikanth@team-group.com | I23: 45874 | J23: New Hire | K23: Direct Hire | L23: Salary | M23: 250728022 | N23: John | O23: JD | P23: Doe | Q23: JD | R23: VP | S23: Form Cambridge | T23: 123 | U23: VS | V23: Vishal.srikanth@team-group.com | AF23: Required | BB23: 123 | BF23: Vish | BG23: 45866 | BO23: REQ-1753710374600
E24: Yes | F24: 45866 | G24: Vish | H24: Vishal.srikanth@team-group.com | I24: 45866 | J24: New Hire | K24: Direct Hire | L24: Salary | M24: 250728023 | N24: John | O24: JD | P24: Doe | Q24: JD | R24: VP | S24: Form Cambridge | BF24: Vish | BG24: 45866 | BO24: REQ-1753710733135
E25: Yes | F25: 45866 | G25: Vish | H25: Vishal.srikanth@team-group.com | I25: 45874 | J25: New Hire | K25: Direct Hire | L25: Salary | M25: 250728024 | N25: John | O25: JD | P25: Doe | Q25: JD | BF25: Vish | BG25: 45866 | BO25: REQ-1753711057797 | BP25: test@gmail.com | BQ25: 123 | BW25: 45866 | BY25: test
E26: Yes | F26: 45866 | G26: Vish | H26: Vishal.srikanth@team-group.com | I26: 45874 | J26: New Hire | K26: Direct Hire | L26: Hourly | M26: 250728025 | N26: John | BG26: 45866 | BO26: REQ-1753712267593 | BP26: test@gmail.com | BQ26: 123 | BW26: 45866 | BY26: test
E27: Yes | F27: 45866 | G27: Vish | H27: Vishal.srikanth@team-group.com | I27: 45866 | J27: New Hire | K27: Direct Hire | L27: Salary | M27: 250728026 | N27: John | O27: JD | P27: Doe | Q27: JD | R27: VP | S27: Form Cambridge | BF27: Vish | BO27: REQ-1753712881052 | BP27: test@gmail.com | BQ27: 123 | BW27: 45866
E28: Yes | F28: 45866 | M28: 250728027 | BO28: REQ-1753712890623 | BP28: test@gmail.com | BQ28: 123 | BW28: 45866
E29: Yes | F29: 45866 | G29: Vish | M29: 250728028 | BO29: REQ-1753712892388 | BP29: test@gmail.com | BQ29: 123 | BW29: 45866 | BY29: test
E30: Yes | F30: 45866 | M30: 250728029 | BO30: REQ-1753713540080
E31: Yes | F31: 45866 | G31: Vish | M31: 250728030 | BO31: REQ-1753713541006
E32: Yes | F32: 45866 | G32: Vish | H32: Vishal.srikanth@team-group.com | I32: 45866 | J32: New Hire | K32: Direct Hire | L32: Hourly | M32: 250728031 | N32: John | O32: JD | P32: Doe | Q32: JD | U32: VS | V32: Vishal.srikanth@team-group.com | BF32: Vish | BG32: 45866 | BO32: REQ-1753713613796 | BP32: test@gmail.com | BQ32: 123 | BW32: 45866 | BX32: Approved
E33: Yes | F33: 45866 | G33: Vish | H33: Vishal.srikanth@team-group.com | I33: 45866 | J33: New Hire | K33: Direct Hire | L33: Hourly | M33: 250728032 | N33: John | O33: JD | P33: Doe | Q33: JD | R33: VP | S33: Form Cambridge | T33: 123 | U33: VS | V33: Vishal.srikanth@team-group.com | AP33: Required | AU33: Yes | AV33: usnm | AW33: 123 | BF33: Vish | BG33: 45866 | BO33: REQ-1753714423582 | BP33: test@gmail.com | BQ33: 123 | BW33: 45866 | BX33: Approved | BY33: test
E34: Yes | F34: 45866 | G34: Vish | H34: Vishal.srikanth@team-group.com | I34: 45875 | J34: New Hire | K34: Direct Hire | L34: Salary | M34: 250728033 | N34: John | O34: JD | P34: Doe | Q34: JD | R34: VP | S34: Form Cambridge | T34: 123 | U34: VS | V34: Vishal.srikanth@team-group.com | W34: Required | Z34: Required | AP34: Required | AQ34: Required | AS34: Yes | AT34: usnm | AU34: Yes | AV34: usnm | AW34: 123 | AX34: 123, 123 | BF34: Vish | BG34: 45866 | BO34: REQ-1753714741932
E35: Yes | F35: 45866 | G35: Jane Doe | H35: Vishal.srikanth@team-group.com | I35: 45873 | J35: New Hire | K35: Direct Hire | L35: Salary | M35: 250728034 | N35: John | O35: JD | P35: Doe | Q35: JD | R35: VP | S35: Form Cambridge | T35: 123 | U35: Jane Doe | V35: Vishal.srikanth@team-group.com | W35: Required | X35: Required | Y35: Required | Z35: Required | AA35: Required | AB35: Required | AC35: Required | AD35: Required | AE35: Required | AF35: Required | AG35: Required | AI35: Required | AJ35: Required | AK35: Required | AL35: Required | AM35: Required | AN35: Required | AO35: Required | AP35: Required | AQ35: Required | AR35: Required | AS35: Yes | AT35: usnm | AU35: Yes | AV35: usnm | AW35: 123 | AX35: 123 | AY35: 123 | AZ35: 123, 123, 123, 123 | BB35: 123 | BC35: Yes | BD35: Yes | BE35: none | BF35: Jane Doe | BG35: 45866 | BO35: REQ-1753716743848
E36: Yes | F36: 45866 | G36: Jane Doe | H36: Vishal.srikanth@team-group.com | I36: 45866 | J36: New Hire | K36: Direct Hire | L36: Hourly | M36: 250728035 | N36: John | O36: JD | P36: Doe | Q36: JD | R36: VP | S36: Form Cambridge | T36: 123 | U36: Jane Doe | V36: Vishal.srikanth@team-group.com | W36: Required | Z36: Required | AC36: Required | AE36: Required | AO36: Required | AP36: Required | AQ36: Required | AS36: Yes | AT36: usnm | AU36: Yes | AV36: usnm | AW36: 123 | AX36: 123 | AY36: 123 | BA36: 123 | BF36: Vish | BH36: Required | BI36: Yes | BJ36: john.doe@company.com | BO36: REQ-1753718542202 | BQ36: 123 | BR36: 123 | BS36: 123 | BT36: Yes | BW36: 45866
E37: Yes | F37: 45866 | G37: Jane Doe | H37: Vishal.srikanth@team-group.com | I37: 45866 | J37: New Hire | K37: Direct Hire | L37: Hourly | M37: 250728036 | N37: John | O37: JD | P37: Doe | Q37: JD | R37: VP | S37: Form Cambridge | T37: 123 | U37: Jane Doe | V37: Vishal.srikanth@team-group.com | BF37: Jane Doe | BG37: 45866 | BI37: No | BJ37: john.doe@company.com | BO37: REQ-1753719218294 | BQ37: 123 | BR37: 123 | BS37: 123 | BT37: Yes | BW37: 45866 | BX37: Denied | BY37: test
E38: Yes | F38: 45866 | G38: Jane Doe | H38: Vishal.srikanth@team-group.com | I38: 45874 | J38: New Hire | K38: Direct Hire | L38: Hourly | M38: 250728037 | N38: John | O38: JD | P38: Doe | Q38: JD | R38: VP | S38: Form Cambridge | T38: 123 | U38: Jane Doe | V38: Vishal.srikanth@team-group.com | W38: Required | X38: Required | Y38: Required | Z38: Required | AA38: Required | AB38: Required | AC38: Required | AD38: Required | AE38: Required | AF38: Required | AG38: Required | AI38: Required | AJ38: Required | AK38: Required | AL38: Required | AM38: Required | AN38: Required | AO38: Required | AP38: Required | AQ38: Required | AR38: Required | AS38: Yes | AT38: usnm | AU38: Yes | AV38: usnm | AW38: 123 | AX38: 123, 123, 123, 123 | AY38: 123 | BA38: 123 | BB38: 123 | BC38: Yes | BD38: Yes | BE38: none | BF38: Jane Doe | BG38: 45866 | BH38: Required | BI38: Yes | BJ38: john.doe@company.com | BO38: REQ-1753720221560
E39: Yes | F39: 45866 | G39: Jane Doe | H39: Vishal.srikanth@team-group.com | I39: 45874 | J39: New Hire | K39: Direct Hire | L39: Hourly | M39: 250728038 | N39: John | O39: JD | P39: Doe | Q39: JD | R39: VP | S39: Form Cambridge | T39: 123 | U39: VS | V39: Vishal.srikanth@team-group.com | BF39: Jane Doe | BG39: 45866 | BI39: No | BJ39: john.doe@company.com | BO39: REQ-1753726357468 | BQ39: 123 | BR39: 123 | BS39: 123 | BT39: Yes | BW39: 45866
E40: Yes | F40: 45866 | G40: Jane Doe | H40: Vishal.srikanth@team-group.com | I40: 45866 | J40: New Hire | K40: Direct Hire | L40: Hourly | M40: 250728039 | N40: John | O40: JD | P40: Doe | Q40: JD | R40: VP | S40: Form Cambridge | T40: 123 | U40: Jane Doe | V40: Vishal.srikanth@team-group.com | BF40: Jane Doe | BG40: 45866 | BI40: No | BJ40: john.doe@company.com | BO40: REQ-1753726497095
...

Sheet Sheet5

Sheet Tasks
A1: Task ID | B1: Workflow ID | C1: Task Type | D1: Status | E1: Assigned To | F1: Started At | G1: Completed At | H1: Data | I1: Metadata | J1: External Ticket ID | K1: External System | L1: Last Synced At

Sheet Workflows
A1: Workflow ID | B1: Workflow Type | C1: Status | D1: Initiated By | E1: Initiated At | F1: Completed At | G1: Metadata
A2: WF-NEWHIRE-1764104102576 | B2: NewHire | C2: Complete | D2: hr@team-group.com | E2: 45986.663 | F2: 45986.663 | G2: {"First Name":"Test","Last Name":"Employee","Requester Email":"test@team-group.com","Department":"IT","Reporting Manager":"Manager Name","Credit Card":"Yes","Fleetio / Vehicle":"Yes","JR":"Yes","30-60-90":"Yes","ADP Supervisor Access":"No","ADP Manager Access":"No","JONAS":"No","SiteDocs":"No"}

Sheet Employee Directory
A1: Employee ID | B1: First Name | C1: Middle Name | D1: Last Name | E1: Preferred Name | F1: Position / Job Title | G1: Email Address | H1: Phone Number | I1: Hourly or Salary | J1: Hire Date | K1: Site Name | L1: Site Number | M1: Reporting Manager Name | N1: Reporting Manager Email | O1: Google Account | P1: Business Card | Q1: 30-60-90 | R1: ADP Manager Access | S1: BOSS User Account | T1: Cost Sheet | U1: Leader Access | V1: Trip Reports Access | W1: JR | X1: JONAS Purchasing | Y1: JONAS Field Time | Z1: JOANS EBI | AA1: Incidents | AB1: SiteDocs Training | AC1: CAA | AD1: Fleetio / Vehicle | AE1: Credit Card | AF1: Delivery App | AG1: Mobile Phone | AH1: Computer | AI1: SiteDocs Tablet
A2: =IFERROR(__xludf.DUMMYFUNCTION("FILTER('All Responses'!M:M, 'All Responses'!C:C = ""Completed"")"),2.5072906E8) -> 250729060 | B2: =IFERROR(__xludf.DUMMYFUNCTION("FILTER('All Responses'!N:N, 'All Responses'!C:C = ""Completed"")"),"John") -> John | C2: =IFERROR(__xludf.DUMMYFUNCTION("FILTER('All Responses'!O:O, 'All Responses'!C:C = ""Completed"")"),"JD") -> JD | D2: =IFERROR(__xludf.DUMMYFUNCTION("FILTER('All Responses'!P:P, 'All Responses'!C:C = ""Completed"")"),"Doe") -> Doe | E2: =IFERROR(__xludf.DUMMYFUNCTION("FILTER('All Responses'!Q:Q, 'All Responses'!C:C = ""Completed"")"),"JD") -> JD | F2: =IFERROR(__xludf.DUMMYFUNCTION("FILTER('All Responses'!R:R, 'All Responses'!C:C = ""Completed"")"),"VP") -> VP | G2: =IFERROR(__xludf.DUMMYFUNCTION("FILTER('All Responses'!CJ:CJ, 'All Responses'!C:C = ""Completed"")"),"") | H2: =IFERROR(__xludf.DUMMYFUNCTION("FILTER('All Responses'!CL:CL, 'All Responses'!C:C = ""Completed"")"),123.0) -> 123 | I2: =IFERROR(__xludf.DUMMYFUNCTION("FILTER('All Responses'!L:L, 'All Responses'!C:C = ""Completed"")"),"Hourly") -> Hourly | J2: =IFERROR(__xludf.DUMMYFUNCTION("FILTER('All Responses'!I:I, 'All Responses'!C:C = ""Completed"")"),"") | K2: =IFERROR(__xludf.DUMMYFUNCTION("FILTER('All Responses'!S:S, 'All Responses'!C:C = ""Completed"")"),"Decostar") -> Decostar | L2: =IFERROR(__xludf.DUMMYFUNCTION("FILTER('All Responses'!T:T, 'All Responses'!C:C = ""Completed"")"),"TEST3") -> TEST3 | M2: =IFERROR(__xludf.DUMMYFUNCTION("FILTER('All Responses'!U:U, 'All Responses'!C:C = ""Completed"")"),"VS") -> VS | N2: =IFERROR(__xludf.DUMMYFUNCTION("FILTER('All Responses'!V:V, 'All Responses'!C:C = ""Completed"")"),"Vishal.srikanth@team-group.com") -> Vishal.srikanth@team-group.com | O2: =IFERROR(__xludf.DUMMYFUNCTION("FILTER('All Responses'!AN:AN, 'All Responses'!C:C = ""Completed"")"),"Required") -> Required | P2: =IFERROR(__xludf.DUMMYFUNCTION("FILTER('All Responses'!W:W, 'All Responses'!C:C = ""Completed"")"),"") | Q2: =IFERROR(__xludf.DUMMYFUNCTION("FILTER('All Responses'!X:X, 'All Responses'!C:C = ""Completed"")"),"") | R2: =IFERROR(__xludf.DUMMYFUNCTION("FILTER('All Responses'!Y:Y, 'All Responses'!C:C = ""Completed"")"),"") | S2: =IFERROR(__xludf.DUMMYFUNCTION("FILTER('All Responses'!BH:BH, 'All Responses'!C:C = ""Completed"")"),"") | T2: =IFERROR(__xludf.DUMMYFUNCTION("FILTER('All Responses'!Z:Z, 'All Responses'!C:C = ""Completed"")"),"") | U2: =IFERROR(__xludf.DUMMYFUNCTION("FILTER('All Responses'!AA:AA, 'All Responses'!C:C = ""Completed"")"),"") | V2: =IFERROR(__xludf.DUMMYFUNCTION("FILTER('All Responses'!AB:AB, 'All Responses'!C:C = ""Completed"")"),"") | W2: =IFERROR(__xludf.DUMMYFUNCTION("FILTER('All Responses'!AC:AC, 'All Responses'!C:C = ""Completed"")"),"") | X2: =IFERROR(__xludf.DUMMYFUNCTION("FILTER('All Responses'!AD:AD, 'All Responses'!C:C = ""Completed"")"),"") | Y2: =IFERROR(__xludf.DUMMYFUNCTION("FILTER('All Responses'!AE:AE, 'All Responses'!C:C = ""Completed"")"),"") | Z2: =IFERROR(__xludf.DUMMYFUNCTION("FILTER('All Responses'!AF:AF, 'All Responses'!C:C = ""Completed"")"),"") | AA2: =IFERROR(__xludf.DUMMYFUNCTION("FILTER('All Responses'!AG:AG, 'All Responses'!C:C = ""Completed"")"),"") | AB2: =IFERROR(__xludf.DUMMYFUNCTION("FILTER('All Responses'!AH:AH, 'All Responses'!C:C = ""Completed"")"),"") | AC2: =IFERROR(__xludf.DUMMYFUNCTION("FILTER('All Responses'!AI:AI, 'All Responses'!C:C = ""Completed"")"),"") | AD2: =IFERROR(__xludf.DUMMYFUNCTION("FILTER('All Responses'!AL:AL, 'All Responses'!C:C = ""Completed"")"),"") | AE2: =IFERROR(__xludf.DUMMYFUNCTION("FILTER('All Responses'!AM:AM, 'All Responses'!C:C = ""Completed"")"),"") | AF2: =IFERROR(__xludf.DUMMYFUNCTION("FILTER('All Responses'!AO:AO, 'All Responses'!C:C = ""Completed"")"),"") | AG2: =IFERROR(__xludf.DUMMYFUNCTION("FILTER('All Responses'!AP:AP, 'All Responses'!C:C = ""Completed"")"),"Required") -> Required | AH2: =IFERROR(__xludf.DUMMYFUNCTION("FILTER('All Responses'!AQ:AQ, 'All Responses'!C:C = ""Completed"")"),"Required") -> Required | AI2: =IFERROR(__xludf.DUMMYFUNCTION("FILTER('All Responses'!AR:AR, 'All Responses'!C:C = ""Completed"")"),"")
A3: =IFERROR(__xludf.DUMMYFUNCTION("""COMPUTED_VALUE"""),2.50729062E8) -> 250729062 | B3: =IFERROR(__xludf.DUMMYFUNCTION("""COMPUTED_VALUE"""),"John") -> John | C3: =IFERROR(__xludf.DUMMYFUNCTION("""COMPUTED_VALUE"""),"z") -> z | D3: =IFERROR(__xludf.DUMMYFUNCTION("""COMPUTED_VALUE"""),"Doe") -> Doe | E3: =IFERROR(__xludf.DUMMYFUNCTION("""COMPUTED_VALUE"""),"JZ") -> JZ | F3: =IFERROR(__xludf.DUMMYFUNCTION("""COMPUTED_VALUE"""),"VP") -> VP | I3: =IFERROR(__xludf.DUMMYFUNCTION("""COMPUTED_VALUE"""),"Hourly") -> Hourly | J3: =IFERROR(__xludf.DUMMYFUNCTION("""COMPUTED_VALUE"""),45875.0) -> 45875 | K3: =IFERROR(__xludf.DUMMYFUNCTION("""COMPUTED_VALUE"""),"Etobicote") -> Etobicote | L3: =IFERROR(__xludf.DUMMYFUNCTION("""COMPUTED_VALUE"""),"TEST5") -> TEST5 | M3: =IFERROR(__xludf.DUMMYFUNCTION("""COMPUTED_VALUE"""),"Jane Doe") -> Jane Doe | N3: =IFERROR(__xludf.DUMMYFUNCTION("""COMPUTED_VALUE"""),"Vishal.srikanth@team-group.com") -> Vishal.srikanth@team-group.com
A4: =IFERROR(__xludf.DUMMYFUNCTION("""COMPUTED_VALUE"""),2.50729063E8) -> 250729063 | B4: =IFERROR(__xludf.DUMMYFUNCTION("""COMPUTED_VALUE"""),"John") -> John | C4: =IFERROR(__xludf.DUMMYFUNCTION("""COMPUTED_VALUE"""),"JD") -> JD | D4: =IFERROR(__xludf.DUMMYFUNCTION("""COMPUTED_VALUE"""),"Doe") -> Doe | E4: =IFERROR(__xludf.DUMMYFUNCTION("""COMPUTED_VALUE"""),"JD") -> JD | F4: =IFERROR(__xludf.DUMMYFUNCTION("""COMPUTED_VALUE"""),"VP") -> VP | G4: =IFERROR(__xludf.DUMMYFUNCTION("""COMPUTED_VALUE"""),"email") -> email | H4: =IFERROR(__xludf.DUMMYFUNCTION("""COMPUTED_VALUE"""),123.0) -> 123 | I4: =IFERROR(__xludf.DUMMYFUNCTION("""COMPUTED_VALUE"""),"Hourly") -> Hourly | J4: =IFERROR(__xludf.DUMMYFUNCTION("""COMPUTED_VALUE"""),45876.0) -> 45876 | K4: =IFERROR(__xludf.DUMMYFUNCTION("""COMPUTED_VALUE"""),"Decostar") -> Decostar | L4: =IFERROR(__xludf.DUMMYFUNCTION("""COMPUTED_VALUE"""),"TEST3") -> TEST3 | M4: =IFERROR(__xludf.DUMMYFUNCTION("""COMPUTED_VALUE"""),"Jane Doe") -> Jane Doe | N4: =IFERROR(__xludf.DUMMYFUNCTION("""COMPUTED_VALUE"""),"Vishal.srikanth@team-group.com") -> Vishal.srikanth@team-group.com | O4: =IFERROR(__xludf.DUMMYFUNCTION("""COMPUTED_VALUE"""),"Required") -> Required | P4: =IFERROR(__xludf.DUMMYFUNCTION("""COMPUTED_VALUE"""),"Required") -> Required | Q4: =IFERROR(__xludf.DUMMYFUNCTION("""COMPUTED_VALUE"""),"Required") -> Required | R4: =IFERROR(__xludf.DUMMYFUNCTION("""COMPUTED_VALUE"""),"Required") -> Required | S4: =IFERROR(__xludf.DUMMYFUNCTION("""COMPUTED_VALUE"""),"Required") -> Required | T4: =IFERROR(__xludf.DUMMYFUNCTION("""COMPUTED_VALUE"""),"Required") -> Required | U4: =IFERROR(__xludf.DUMMYFUNCTION("""COMPUTED_VALUE"""),"Required") -> Required | V4: =IFERROR(__xludf.DUMMYFUNCTION("""COMPUTED_VALUE"""),"Required") -> Required | ... AI4: =IFERROR(__xludf.DUMMYFUNCTION("""COMPUTED_VALUE"""),"Required") -> Required
A5: =IFERROR(__xludf.DUMMYFUNCTION("""COMPUTED_VALUE"""),2.50729064E8) -> 250729064 | B5: =IFERROR(__xludf.DUMMYFUNCTION("""COMPUTED_VALUE"""),"John") -> John | C5: =IFERROR(__xludf.DUMMYFUNCTION("""COMPUTED_VALUE"""),"JD") -> JD | D5: =IFERROR(__xludf.DUMMYFUNCTION("""COMPUTED_VALUE"""),"Doe") -> Doe | E5: =IFERROR(__xludf.DUMMYFUNCTION("""COMPUTED_VALUE"""),"JD") -> JD | F5: =IFERROR(__xludf.DUMMYFUNCTION("""COMPUTED_VALUE"""),"VP") -> VP | H5: =IFERROR(__xludf.DUMMYFUNCTION("""COMPUTED_VALUE"""),123.0) -> 123 | I5: =IFERROR(__xludf.DUMMYFUNCTION("""COMPUTED_VALUE"""),"Salary") -> Salary | J5: =IFERROR(__xludf.DUMMYFUNCTION("""COMPUTED_VALUE"""),45875.0) -> 45875 | K5: =IFERROR(__xludf.DUMMYFUNCTION("""COMPUTED_VALUE"""),"Etobicote") -> Etobicote | L5: =IFERROR(__xludf.DUMMYFUNCTION("""COMPUTED_VALUE"""),"TEST5") -> TEST5 | M5: =IFERROR(__xludf.DUMMYFUNCTION("""COMPUTED_VALUE"""),"Jane Doe") -> Jane Doe | N5: =IFERROR(__xludf.DUMMYFUNCTION("""COMPUTED_VALUE"""),"Vishal.srikanth@team-group.com") -> Vishal.srikanth@team-group.com | O5: =IFERROR(__xludf.DUMMYFUNCTION("""COMPUTED_VALUE"""),"Required") -> Required | P5: =IFERROR(__xludf.DUMMYFUNCTION("""COMPUTED_VALUE"""),"Required") -> Required | Q5: =IFERROR(__xludf.DUMMYFUNCTION("""COMPUTED_VALUE"""),"Required") -> Required | R5: =IFERROR(__xludf.DUMMYFUNCTION("""COMPUTED_VALUE"""),"Required") -> Required | S5: =IFERROR(__xludf.DUMMYFUNCTION("""COMPUTED_VALUE"""),"Required") -> Required | T5: =IFERROR(__xludf.DUMMYFUNCTION("""COMPUTED_VALUE"""),"Required") -> Required | U5: =IFERROR(__xludf.DUMMYFUNCTION("""COMPUTED_VALUE"""),"Required") -> Required | V5: =IFERROR(__xludf.DUMMYFUNCTION("""COMPUTED_VALUE"""),"Required") -> Required | ... AI5: =IFERROR(__xludf.DUMMYFUNCTION("""COMPUTED_VALUE"""),"Required") -> Required
A6: =IFERROR(__xludf.DUMMYFUNCTION("""COMPUTED_VALUE"""),2.50729065E8) -> 250729065 | B6: =IFERROR(__xludf.DUMMYFUNCTION("""COMPUTED_VALUE"""),"John") -> John | C6: =IFERROR(__xludf.DUMMYFUNCTION("""COMPUTED_VALUE"""),"JD") -> JD | D6: =IFERROR(__xludf.DUMMYFUNCTION("""COMPUTED_VALUE"""),"Doe") -> Doe | E6: =IFERROR(__xludf.DUMMYFUNCTION("""COMPUTED_VALUE"""),"JD") -> JD | F6: =IFERROR(__xludf.DUMMYFUNCTION("""COMPUTED_VALUE"""),"VP") -> VP | H6: =IFERROR(__xludf.DUMMYFUNCTION("""COMPUTED_VALUE"""),123.0) -> 123 | I6: =IFERROR(__xludf.DUMMYFUNCTION("""COMPUTED_VALUE"""),"Salary") -> Salary | J6: =IFERROR(__xludf.DUMMYFUNCTION("""COMPUTED_VALUE"""),45875.0) -> 45875 | K6: =IFERROR(__xludf.DUMMYFUNCTION("""COMPUTED_VALUE"""),"Etobicote") -> Etobicote | L6: =IFERROR(__xludf.DUMMYFUNCTION("""COMPUTED_VALUE"""),"TEST5") -> TEST5 | M6: =IFERROR(__xludf.DUMMYFUNCTION("""COMPUTED_VALUE"""),"VS") -> VS | N6: =IFERROR(__xludf.DUMMYFUNCTION("""COMPUTED_VALUE"""),"Vishal.srikanth@team-group.com") -> Vishal.srikanth@team-group.com | O6: =IFERROR(__xludf.DUMMYFUNCTION("""COMPUTED_VALUE"""),"Required") -> Required | P6: =IFERROR(__xludf.DUMMYFUNCTION("""COMPUTED_VALUE"""),"Required") -> Required | Q6: =IFERROR(__xludf.DUMMYFUNCTION("""COMPUTED_VALUE"""),"Required") -> Required | R6: =IFERROR(__xludf.DUMMYFUNCTION("""COMPUTED_VALUE"""),"Required") -> Required | S6: =IFERROR(__xludf.DUMMYFUNCTION("""COMPUTED_VALUE"""),"Required") -> Required | T6: =IFERROR(__xludf.DUMMYFUNCTION("""COMPUTED_VALUE"""),"Required") -> Required | Z6: =IFERROR(__xludf.DUMMYFUNCTION("""COMPUTED_VALUE"""),"Required") -> Required | AG6: =IFERROR(__xludf.DUMMYFUNCTION("""COMPUTED_VALUE"""),"Required") -> Required | AH6: =IFERROR(__xludf.DUMMYFUNCTION("""COMPUTED_VALUE"""),"Required") -> Required
A7: =IFERROR(__xludf.DUMMYFUNCTION("""COMPUTED_VALUE"""),2.50729066E8) -> 250729066 | B7: =IFERROR(__xludf.DUMMYFUNCTION("""COMPUTED_VALUE"""),"John") -> John | C7: =IFERROR(__xludf.DUMMYFUNCTION("""COMPUTED_VALUE"""),"JD") -> JD | D7: =IFERROR(__xludf.DUMMYFUNCTION("""COMPUTED_VALUE"""),"Doe") -> Doe | E7: =IFERROR(__xludf.DUMMYFUNCTION("""COMPUTED_VALUE"""),"JD") -> JD | F7: =IFERROR(__xludf.DUMMYFUNCTION("""COMPUTED_VALUE"""),"VP") -> VP | I7: =IFERROR(__xludf.DUMMYFUNCTION("""COMPUTED_VALUE"""),"Hourly") -> Hourly | J7: =IFERROR(__xludf.DUMMYFUNCTION("""COMPUTED_VALUE"""),45875.0) -> 45875 | K7: =IFERROR(__xludf.DUMMYFUNCTION("""COMPUTED_VALUE"""),"Edmonton") -> Edmonton | L7: =IFERROR(__xludf.DUMMYFUNCTION("""COMPUTED_VALUE"""),"TEST4") -> TEST4 | M7: =IFERROR(__xludf.DUMMYFUNCTION("""COMPUTED_VALUE"""),"Jane Doe") -> Jane Doe | O7: =IFERROR(__xludf.DUMMYFUNCTION("""COMPUTED_VALUE"""),"Required") -> Required | S7: =IFERROR(__xludf.DUMMYFUNCTION("""COMPUTED_VALUE"""),"Required") -> Required | T7: =IFERROR(__xludf.DUMMYFUNCTION("""COMPUTED_VALUE"""),"Required") -> Required | U7: =IFERROR(__xludf.DUMMYFUNCTION("""COMPUTED_VALUE"""),"Required") -> Required | AF7: =IFERROR(__xludf.DUMMYFUNCTION("""COMPUTED_VALUE"""),"Required") -> Required | AH7: =IFERROR(__xludf.DUMMYFUNCTION("""COMPUTED_VALUE"""),"Required") -> Required
A8: =IFERROR(__xludf.DUMMYFUNCTION("""COMPUTED_VALUE"""),2.50730001E8) -> 250730001 | B8: =IFERROR(__xludf.DUMMYFUNCTION("""COMPUTED_VALUE"""),"John") -> John | C8: =IFERROR(__xludf.DUMMYFUNCTION("""COMPUTED_VALUE"""),"JD") -> JD | D8: =IFERROR(__xludf.DUMMYFUNCTION("""COMPUTED_VALUE"""),"Doe") -> Doe | E8: =IFERROR(__xludf.DUMMYFUNCTION("""COMPUTED_VALUE"""),"JD") -> JD | F8: =IFERROR(__xludf.DUMMYFUNCTION("""COMPUTED_VALUE"""),"VP") -> VP | H8: =IFERROR(__xludf.DUMMYFUNCTION("""COMPUTED_VALUE"""),123.0) -> 123 | I8: =IFERROR(__xludf.DUMMYFUNCTION("""COMPUTED_VALUE"""),"Salary") -> Salary | J8: =IFERROR(__xludf.DUMMYFUNCTION("""COMPUTED_VALUE"""),45876.0) -> 45876 | K8: =IFERROR(__xludf.DUMMYFUNCTION("""COMPUTED_VALUE"""),"Bluebird") -> Bluebird | L8: =IFERROR(__xludf.DUMMYFUNCTION("""COMPUTED_VALUE"""),"TEST1") -> TEST1 | M8: =IFERROR(__xludf.DUMMYFUNCTION("""COMPUTED_VALUE"""),"Jane Doe") -> Jane Doe | N8: =IFERROR(__xludf.DUMMYFUNCTION("""COMPUTED_VALUE"""),"Vishal.srikanth@team-group.com") -> Vishal.srikanth@team-group.com | O8: =IFERROR(__xludf.DUMMYFUNCTION("""COMPUTED_VALUE"""),"Required") -> Required | P8: =IFERROR(__xludf.DUMMYFUNCTION("""COMPUTED_VALUE"""),"Required") -> Required | Q8: =IFERROR(__xludf.DUMMYFUNCTION("""COMPUTED_VALUE"""),"Required") -> Required | R8: =IFERROR(__xludf.DUMMYFUNCTION("""COMPUTED_VALUE"""),"Required") -> Required | S8: =IFERROR(__xludf.DUMMYFUNCTION("""COMPUTED_VALUE"""),"Required") -> Required | T8: =IFERROR(__xludf.DUMMYFUNCTION("""COMPUTED_VALUE"""),"Required") -> Required | U8: =IFERROR(__xludf.DUMMYFUNCTION("""COMPUTED_VALUE"""),"Required") -> Required | V8: =IFERROR(__xludf.DUMMYFUNCTION("""COMPUTED_VALUE"""),"Required") -> Required | ... AI8: =IFERROR(__xludf.DUMMYFUNCTION("""COMPUTED_VALUE"""),"Required") -> Required
A9: =IFERROR(__xludf.DUMMYFUNCTION("""COMPUTED_VALUE"""),2.50730003E8) -> 250730003 | B9: =IFERROR(__xludf.DUMMYFUNCTION("""COMPUTED_VALUE"""),"John") -> John | C9: =IFERROR(__xludf.DUMMYFUNCTION("""COMPUTED_VALUE"""),"JD") -> JD | D9: =IFERROR(__xludf.DUMMYFUNCTION("""COMPUTED_VALUE"""),"Doe") -> Doe | E9: =IFERROR(__xludf.DUMMYFUNCTION("""COMPUTED_VALUE"""),"JD") -> JD | F9: =IFERROR(__xludf.DUMMYFUNCTION("""COMPUTED_VALUE"""),"VP") -> VP | H9: =IFERROR(__xludf.DUMMYFUNCTION("""COMPUTED_VALUE"""),123.0) -> 123 | I9: =IFERROR(__xludf.DUMMYFUNCTION("""COMPUTED_VALUE"""),"Salary") -> Salary | J9: =IFERROR(__xludf.DUMMYFUNCTION("""COMPUTED_VALUE"""),45875.0) -> 45875 | K9: =IFERROR(__xludf.DUMMYFUNCTION("""COMPUTED_VALUE"""),"Edmonton") -> Edmonton | L9: =IFERROR(__xludf.DUMMYFUNCTION("""COMPUTED_VALUE"""),"TEST4") -> TEST4 | M9: =IFERROR(__xludf.DUMMYFUNCTION("""COMPUTED_VALUE"""),"Jane Doe") -> Jane Doe | N9: =IFERROR(__xludf.DUMMYFUNCTION("""COMPUTED_VALUE"""),"Vishal.srikanth@team-group.com") -> Vishal.srikanth@team-group.com | O9: =IFERROR(__xludf.DUMMYFUNCTION("""COMPUTED_VALUE"""),"Required") -> Required | P9: =IFERROR(__xludf.DUMMYFUNCTION("""COMPUTED_VALUE"""),"Required") -> Required | R9: =IFERROR(__xludf.DUMMYFUNCTION("""COMPUTED_VALUE"""),"Required") -> Required | W9: =IFERROR(__xludf.DUMMYFUNCTION("""COMPUTED_VALUE"""),"Required") -> Required | Y9: =IFERROR(__xludf.DUMMYFUNCTION("""COMPUTED_VALUE"""),"Required") -> Required | AD9: =IFERROR(__xludf.DUMMYFUNCTION("""COMPUTED_VALUE"""),"Required") -> Required | AG9: =IFERROR(__xludf.DUMMYFUNCTION("""COMPUTED_VALUE"""),"Required") -> Required
A10: =IFERROR(__xludf.DUMMYFUNCTION("""COMPUTED_VALUE"""),2.50730004E8) -> 250730004 | B10: =IFERROR(__xludf.DUMMYFUNCTION("""COMPUTED_VALUE"""),"John") -> John | C10: =IFERROR(__xludf.DUMMYFUNCTION("""COMPUTED_VALUE"""),"JD") -> JD | D10: =IFERROR(__xludf.DUMMYFUNCTION("""COMPUTED_VALUE"""),"Doe") -> Doe | E10: =IFERROR(__xludf.DUMMYFUNCTION("""COMPUTED_VALUE"""),"JD") -> JD | F10: =IFERROR(__xludf.DUMMYFUNCTION("""COMPUTED_VALUE"""),"VP") -> VP | H10: =IFERROR(__xludf.DUMMYFUNCTION("""COMPUTED_VALUE"""),123.0) -> 123 | I10: =IFERROR(__xludf.DUMMYFUNCTION("""COMPUTED_VALUE"""),"Salary") -> Salary | J10: =IFERROR(__xludf.DUMMYFUNCTION("""COMPUTED_VALUE"""),45877.0) -> 45877 | K10: =IFERROR(__xludf.DUMMYFUNCTION("""COMPUTED_VALUE"""),"Edmonton") -> Edmonton | L10: =IFERROR(__xludf.DUMMYFUNCTION("""COMPUTED_VALUE"""),"TEST4") -> TEST4 | M10: =IFERROR(__xludf.DUMMYFUNCTION("""COMPUTED_VALUE"""),"Jane Doe") -> Jane Doe | N10: =IFERROR(__xludf.DUMMYFUNCTION("""COMPUTED_VALUE"""),"Vishal.srikanth@team-group.com") -> Vishal.srikanth@team-group.com | O10: =IFERROR(__xludf.DUMMYFUNCTION("""COMPUTED_VALUE"""),"Required") -> Required | P10: =IFERROR(__xludf.DUMMYFUNCTION("""COMPUTED_VALUE"""),"Required") -> Required | Q10: =IFERROR(__xludf.DUMMYFUNCTION("""COMPUTED_VALUE"""),"Required") -> Required | R10: =IFERROR(__xludf.DUMMYFUNCTION("""COMPUTED_VALUE"""),"Required") -> Required | S10: =IFERROR(__xludf.DUMMYFUNCTION("""COMPUTED_VALUE"""),"Required") -> Required | T10: =IFERROR(__xludf.DUMMYFUNCTION("""COMPUTED_VALUE"""),"Required") -> Required | U10: =IFERROR(__xludf.DUMMYFUNCTION("""COMPUTED_VALUE"""),"Required") -> Required | V10: =IFERROR(__xludf.DUMMYFUNCTION("""COMPUTED_VALUE"""),"Required") -> Required | ... AI10: =IFERROR(__xludf.DUMMYFUNCTION("""COMPUTED_VALUE"""),"Required") -> Required
A11: =IFERROR(__xludf.DUMMYFUNCTION("""COMPUTED_VALUE"""),2.50730005E8) -> 250730005 | B11: =IFERROR(__xludf.DUMMYFUNCTION("""COMPUTED_VALUE"""),"John") -> John | C11: =IFERROR(__xludf.DUMMYFUNCTION("""COMPUTED_VALUE"""),"JD") -> JD | D11: =IFERROR(__xludf.DUMMYFUNCTION("""COMPUTED_VALUE"""),"Doe") -> Doe | E11: =IFERROR(__xludf.DUMMYFUNCTION("""COMPUTED_VALUE"""),"JD") -> JD | F11: =IFERROR(__xludf.DUMMYFUNCTION("""COMPUTED_VALUE"""),"VP") -> VP | H11: =IFERROR(__xludf.DUMMYFUNCTION("""COMPUTED_VALUE"""),123.0) -> 123 | I11: =IFERROR(__xludf.DUMMYFUNCTION("""COMPUTED_VALUE"""),"Salary") -> Salary | J11: =IFERROR(__xludf.DUMMYFUNCTION("""COMPUTED_VALUE"""),45874.0) -> 45874 | K11: =IFERROR(__xludf.DUMMYFUNCTION("""COMPUTED_VALUE"""),"Bluebird") -> Bluebird | L11: =IFERROR(__xludf.DUMMYFUNCTION("""COMPUTED_VALUE"""),"TEST1") -> TEST1 | M11: =IFERROR(__xludf.DUMMYFUNCTION("""COMPUTED_VALUE"""),"Jane Doe") -> Jane Doe | N11: =IFERROR(__xludf.DUMMYFUNCTION("""COMPUTED_VALUE"""),"Vishal.srikanth@team-group.com") -> Vishal.srikanth@team-group.com | O11: =IFERROR(__xludf.DUMMYFUNCTION("""COMPUTED_VALUE"""),"Required") -> Required | P11: =IFERROR(__xludf.DUMMYFUNCTION("""COMPUTED_VALUE"""),"Required") -> Required | Q11: =IFERROR(__xludf.DUMMYFUNCTION("""COMPUTED_VALUE"""),"Required") -> Required | R11: =IFERROR(__xludf.DUMMYFUNCTION("""COMPUTED_VALUE"""),"Required") -> Required | S11: =IFERROR(__xludf.DUMMYFUNCTION("""COMPUTED_VALUE"""),"Required") -> Required | T11: =IFERROR(__xludf.DUMMYFUNCTION("""COMPUTED_VALUE"""),"Required") -> Required | U11: =IFERROR(__xludf.DUMMYFUNCTION("""COMPUTED_VALUE"""),"Required") -> Required | V11: =IFERROR(__xludf.DUMMYFUNCTION("""COMPUTED_VALUE"""),"Required") -> Required | ... AI11: =IFERROR(__xludf.DUMMYFUNCTION("""COMPUTED_VALUE"""),"Required") -> Required
A12: =IFERROR(__xludf.DUMMYFUNCTION("""COMPUTED_VALUE"""),2.50805002E8) -> 250805002 | B12: =IFERROR(__xludf.DUMMYFUNCTION("""COMPUTED_VALUE"""),"John") -> John | C12: =IFERROR(__xludf.DUMMYFUNCTION("""COMPUTED_VALUE"""),"JD") -> JD | D12: =IFERROR(__xludf.DUMMYFUNCTION("""COMPUTED_VALUE"""),"Doe") -> Doe | E12: =IFERROR(__xludf.DUMMYFUNCTION("""COMPUTED_VALUE"""),"JD") -> JD | F12: =IFERROR(__xludf.DUMMYFUNCTION("""COMPUTED_VALUE"""),"VP") -> VP | H12: =IFERROR(__xludf.DUMMYFUNCTION("""COMPUTED_VALUE"""),123.0) -> 123 | I12: =IFERROR(__xludf.DUMMYFUNCTION("""COMPUTED_VALUE"""),"Salary") -> Salary | J12: =IFERROR(__xludf.DUMMYFUNCTION("""COMPUTED_VALUE"""),45881.0) -> 45881 | K12: =IFERROR(__xludf.DUMMYFUNCTION("""COMPUTED_VALUE"""),"Bluebird") -> Bluebird | L12: =IFERROR(__xludf.DUMMYFUNCTION("""COMPUTED_VALUE"""),"TEST1") -> TEST1 | M12: =IFERROR(__xludf.DUMMYFUNCTION("""COMPUTED_VALUE"""),"VS") -> VS | N12: =IFERROR(__xludf.DUMMYFUNCTION("""COMPUTED_VALUE"""),"Vishal.srikanth@team-group.com") -> Vishal.srikanth@team-group.com | O12: =IFERROR(__xludf.DUMMYFUNCTION("""COMPUTED_VALUE"""),"Required") -> Required | P12: =IFERROR(__xludf.DUMMYFUNCTION("""COMPUTED_VALUE"""),"Required") -> Required | Q12: =IFERROR(__xludf.DUMMYFUNCTION("""COMPUTED_VALUE"""),"Required") -> Required | R12: =IFERROR(__xludf.DUMMYFUNCTION("""COMPUTED_VALUE"""),"Required") -> Required | S12: =IFERROR(__xludf.DUMMYFUNCTION("""COMPUTED_VALUE"""),"Required") -> Required | T12: =IFERROR(__xludf.DUMMYFUNCTION("""COMPUTED_VALUE"""),"Required") -> Required | U12: =IFERROR(__xludf.DUMMYFUNCTION("""COMPUTED_VALUE"""),"Required") -> Required | V12: =IFERROR(__xludf.DUMMYFUNCTION("""COMPUTED_VALUE"""),"Required") -> Required | ... AI12: =IFERROR(__xludf.DUMMYFUNCTION("""COMPUTED_VALUE"""),"Required") -> Required
A13: =IFERROR(__xludf.DUMMYFUNCTION("""COMPUTED_VALUE"""),2.50805006E8) -> 250805006 | B13: =IFERROR(__xludf.DUMMYFUNCTION("""COMPUTED_VALUE"""),"John") -> John | C13: =IFERROR(__xludf.DUMMYFUNCTION("""COMPUTED_VALUE"""),"JD") -> JD | D13: =IFERROR(__xludf.DUMMYFUNCTION("""COMPUTED_VALUE"""),"Doe") -> Doe | E13: =IFERROR(__xludf.DUMMYFUNCTION("""COMPUTED_VALUE"""),"JD") -> JD | F13: =IFERROR(__xludf.DUMMYFUNCTION("""COMPUTED_VALUE"""),"VP") -> VP | G13: =IFERROR(__xludf.DUMMYFUNCTION("""COMPUTED_VALUE"""),"email") -> email | H13: =IFERROR(__xludf.DUMMYFUNCTION("""COMPUTED_VALUE"""),123.0) -> 123 | I13: =IFERROR(__xludf.DUMMYFUNCTION("""COMPUTED_VALUE"""),"Hourly") -> Hourly | J13: =IFERROR(__xludf.DUMMYFUNCTION("""COMPUTED_VALUE"""),45889.0) -> 45889 | K13: =IFERROR(__xludf.DUMMYFUNCTION("""COMPUTED_VALUE"""),"Decostar") -> Decostar | L13: =IFERROR(__xludf.DUMMYFUNCTION("""COMPUTED_VALUE"""),"TEST3") -> TEST3 | M13: =IFERROR(__xludf.DUMMYFUNCTION("""COMPUTED_VALUE"""),"Jane Doe") -> Jane Doe | N13: =IFERROR(__xludf.DUMMYFUNCTION("""COMPUTED_VALUE"""),"Vishal.srikanth@team-group.com") -> Vishal.srikanth@team-group.com | O13: =IFERROR(__xludf.DUMMYFUNCTION("""COMPUTED_VALUE"""),"Yes") -> Yes | P13: =IFERROR(__xludf.DUMMYFUNCTION("""COMPUTED_VALUE"""),"No") -> No | Q13: =IFERROR(__xludf.DUMMYFUNCTION("""COMPUTED_VALUE"""),"No") -> No | R13: =IFERROR(__xludf.DUMMYFUNCTION("""COMPUTED_VALUE"""),"No") -> No | S13: =IFERROR(__xludf.DUMMYFUNCTION("""COMPUTED_VALUE"""),"No") -> No | T13: =IFERROR(__xludf.DUMMYFUNCTION("""COMPUTED_VALUE"""),"No") -> No | U13: =IFERROR(__xludf.DUMMYFUNCTION("""COMPUTED_VALUE"""),"No") -> No | V13: =IFERROR(__xludf.DUMMYFUNCTION("""COMPUTED_VALUE"""),"No") -> No | W13: =IFERROR(__xludf.DUMMYFUNCTION("""COMPUTED_VALUE"""),"No") -> No | ... AD13: =IFERROR(__xludf.DUMMYFUNCTION("""COMPUTED_VALUE"""),"No") -> No | AE13: =IFERROR(__xludf.DUMMYFUNCTION("""COMPUTED_VALUE"""),"Yes") -> Yes | AF13: =IFERROR(__xludf.DUMMYFUNCTION("""COMPUTED_VALUE"""),"No") -> No | AG13: =IFERROR(__xludf.DUMMYFUNCTION("""COMPUTED_VALUE"""),"Yes") -> Yes | AH13: =IFERROR(__xludf.DUMMYFUNCTION("""COMPUTED_VALUE"""),"No") -> No | AI13: =IFERROR(__xludf.DUMMYFUNCTION("""COMPUTED_VALUE"""),"Yes") -> Yes
A14: =IFERROR(__xludf.DUMMYFUNCTION("""COMPUTED_VALUE"""),2.50805007E8) -> 250805007 | B14: =IFERROR(__xludf.DUMMYFUNCTION("""COMPUTED_VALUE"""),"John") -> John | C14: =IFERROR(__xludf.DUMMYFUNCTION("""COMPUTED_VALUE"""),"JD") -> JD | D14: =IFERROR(__xludf.DUMMYFUNCTION("""COMPUTED_VALUE"""),"Doe") -> Doe | F14: =IFERROR(__xludf.DUMMYFUNCTION("""COMPUTED_VALUE"""),"VP") -> VP | I14: =IFERROR(__xludf.DUMMYFUNCTION("""COMPUTED_VALUE"""),"Hourly") -> Hourly | J14: =IFERROR(__xludf.DUMMYFUNCTION("""COMPUTED_VALUE"""),45883.0) -> 45883 | K14: =IFERROR(__xludf.DUMMYFUNCTION("""COMPUTED_VALUE"""),"Decostar") -> Decostar | L14: =IFERROR(__xludf.DUMMYFUNCTION("""COMPUTED_VALUE"""),"TEST3") -> TEST3 | M14: =IFERROR(__xludf.DUMMYFUNCTION("""COMPUTED_VALUE"""),"Jane Doe") -> Jane Doe | N14: =IFERROR(__xludf.DUMMYFUNCTION("""COMPUTED_VALUE"""),"Vishal.srikanth@team-group.com") -> Vishal.srikanth@team-group.com | O14: =IFERROR(__xludf.DUMMYFUNCTION("""COMPUTED_VALUE"""),"No") -> No | P14: =IFERROR(__xludf.DUMMYFUNCTION("""COMPUTED_VALUE"""),"No") -> No | Q14: =IFERROR(__xludf.DUMMYFUNCTION("""COMPUTED_VALUE"""),"No") -> No | R14: =IFERROR(__xludf.DUMMYFUNCTION("""COMPUTED_VALUE"""),"No") -> No | S14: =IFERROR(__xludf.DUMMYFUNCTION("""COMPUTED_VALUE"""),"No") -> No | T14: =IFERROR(__xludf.DUMMYFUNCTION("""COMPUTED_VALUE"""),"No") -> No | U14: =IFERROR(__xludf.DUMMYFUNCTION("""COMPUTED_VALUE"""),"No") -> No | V14: =IFERROR(__xludf.DUMMYFUNCTION("""COMPUTED_VALUE"""),"No") -> No | ... AI14: =IFERROR(__xludf.DUMMYFUNCTION("""COMPUTED_VALUE"""),"No") -> No
A15: =IFERROR(__xludf.DUMMYFUNCTION("""COMPUTED_VALUE"""),2.50806001E8) -> 250806001 | B15: =IFERROR(__xludf.DUMMYFUNCTION("""COMPUTED_VALUE"""),"John") -> John | D15: =IFERROR(__xludf.DUMMYFUNCTION("""COMPUTED_VALUE"""),"Doe") -> Doe | F15: =IFERROR(__xludf.DUMMYFUNCTION("""COMPUTED_VALUE"""),"VP") -> VP | I15: =IFERROR(__xludf.DUMMYFUNCTION("""COMPUTED_VALUE"""),"Hourly") -> Hourly | J15: =IFERROR(__xludf.DUMMYFUNCTION("""COMPUTED_VALUE"""),45904.0) -> 45904 | K15: =IFERROR(__xludf.DUMMYFUNCTION("""COMPUTED_VALUE"""),"Chrysler Windsor Paintshop") -> Chrysler Windsor Paintshop | L15: =IFERROR(__xludf.DUMMYFUNCTION("""COMPUTED_VALUE"""),"TW049") -> TW049 | M15: =IFERROR(__xludf.DUMMYFUNCTION("""COMPUTED_VALUE"""),"Jane Doe") -> Jane Doe | N15: =IFERROR(__xludf.DUMMYFUNCTION("""COMPUTED_VALUE"""),"Vishal.srikanth@team-group.com") -> Vishal.srikanth@team-group.com | O15: =IFERROR(__xludf.DUMMYFUNCTION("""COMPUTED_VALUE"""),"No") -> No | P15: =IFERROR(__xludf.DUMMYFUNCTION("""COMPUTED_VALUE"""),"No") -> No | Q15: =IFERROR(__xludf.DUMMYFUNCTION("""COMPUTED_VALUE"""),"No") -> No | R15: =IFERROR(__xludf.DUMMYFUNCTION("""COMPUTED_VALUE"""),"No") -> No | S15: =IFERROR(__xludf.DUMMYFUNCTION("""COMPUTED_VALUE"""),"No") -> No | T15: =IFERROR(__xludf.DUMMYFUNCTION("""COMPUTED_VALUE"""),"No") -> No | U15: =IFERROR(__xludf.DUMMYFUNCTION("""COMPUTED_VALUE"""),"No") -> No | V15: =IFERROR(__xludf.DUMMYFUNCTION("""COMPUTED_VALUE"""),"No") -> No | ... AD15: =IFERROR(__xludf.DUMMYFUNCTION("""COMPUTED_VALUE"""),"No") -> No | AE15: =IFERROR(__xludf.DUMMYFUNCTION("""COMPUTED_VALUE"""),"Yes") -> Yes | AF15: =IFERROR(__xludf.DUMMYFUNCTION("""COMPUTED_VALUE"""),"No") -> No | AG15: =IFERROR(__xludf.DUMMYFUNCTION("""COMPUTED_VALUE"""),"No") -> No | AH15: =IFERROR(__xludf.DUMMYFUNCTION("""COMPUTED_VALUE"""),"No") -> No | AI15: =IFERROR(__xludf.DUMMYFUNCTION("""COMPUTED_VALUE"""),"No") -> No
A16: =IFERROR(__xludf.DUMMYFUNCTION("""COMPUTED_VALUE"""),2.50806002E8) -> 250806002 | B16: =IFERROR(__xludf.DUMMYFUNCTION("""COMPUTED_VALUE"""),"John") -> John | C16: =IFERROR(__xludf.DUMMYFUNCTION("""COMPUTED_VALUE"""),"JD") -> JD | D16: =IFERROR(__xludf.DUMMYFUNCTION("""COMPUTED_VALUE"""),"Doe") -> Doe | F16: =IFERROR(__xludf.DUMMYFUNCTION("""COMPUTED_VALUE"""),"VP") -> VP | I16: =IFERROR(__xludf.DUMMYFUNCTION("""COMPUTED_VALUE"""),"Hourly") -> Hourly | J16: =IFERROR(__xludf.DUMMYFUNCTION("""COMPUTED_VALUE"""),45894.0) -> 45894 | K16: =IFERROR(__xludf.DUMMYFUNCTION("""COMPUTED_VALUE"""),"Cost Variance - RSI") -> Cost Variance - RSI | L16: =IFERROR(__xludf.DUMMYFUNCTION("""COMPUTED_VALUE"""),171.0) -> 171 | M16: =IFERROR(__xludf.DUMMYFUNCTION("""COMPUTED_VALUE"""),"VS") -> VS | N16: =IFERROR(__xludf.DUMMYFUNCTION("""COMPUTED_VALUE"""),"Vishal.srikanth@team-group.com") -> Vishal.srikanth@team-group.com | O16: =IFERROR(__xludf.DUMMYFUNCTION("""COMPUTED_VALUE"""),"No") -> No | P16: =IFERROR(__xludf.DUMMYFUNCTION("""COMPUTED_VALUE"""),"No") -> No | Q16: =IFERROR(__xludf.DUMMYFUNCTION("""COMPUTED_VALUE"""),"No") -> No | R16: =IFERROR(__xludf.DUMMYFUNCTION("""COMPUTED_VALUE"""),"No") -> No | S16: =IFERROR(__xludf.DUMMYFUNCTION("""COMPUTED_VALUE"""),"No") -> No | T16: =IFERROR(__xludf.DUMMYFUNCTION("""COMPUTED_VALUE"""),"No") -> No | U16: =IFERROR(__xludf.DUMMYFUNCTION("""COMPUTED_VALUE"""),"No") -> No | V16: =IFERROR(__xludf.DUMMYFUNCTION("""COMPUTED_VALUE"""),"No") -> No | ... AI16: =IFERROR(__xludf.DUMMYFUNCTION("""COMPUTED_VALUE"""),"No") -> No
A17: =IFERROR(__xludf.DUMMYFUNCTION("""COMPUTED_VALUE"""),2.50806003E8) -> 250806003 | B17: =IFERROR(__xludf.DUMMYFUNCTION("""COMPUTED_VALUE"""),"John") -> John | C17: =IFERROR(__xludf.DUMMYFUNCTION("""COMPUTED_VALUE"""),"z") -> z | D17: =IFERROR(__xludf.DUMMYFUNCTION("""COMPUTED_VALUE"""),"Doe") -> Doe | E17: =IFERROR(__xludf.DUMMYFUNCTION("""COMPUTED_VALUE"""),"JZ") -> JZ | F17: =IFERROR(__xludf.DUMMYFUNCTION("""COMPUTED_VALUE"""),"VP") -> VP | G17: =IFERROR(__xludf.DUMMYFUNCTION("""COMPUTED_VALUE"""),"email") -> email | H17: =IFERROR(__xludf.DUMMYFUNCTION("""COMPUTED_VALUE"""),123.0) -> 123 | I17: =IFERROR(__xludf.DUMMYFUNCTION("""COMPUTED_VALUE"""),"Hourly") -> Hourly | J17: =IFERROR(__xludf.DUMMYFUNCTION("""COMPUTED_VALUE"""),45896.0) -> 45896 | K17: =IFERROR(__xludf.DUMMYFUNCTION("""COMPUTED_VALUE"""),"Finance") -> Finance | L17: =IFERROR(__xludf.DUMMYFUNCTION("""COMPUTED_VALUE"""),44.0) -> 44 | M17: =IFERROR(__xludf.DUMMYFUNCTION("""COMPUTED_VALUE"""),"Jane Doe") -> Jane Doe | N17: =IFERROR(__xludf.DUMMYFUNCTION("""COMPUTED_VALUE"""),"Vishal.srikanth@team-group.com") -> Vishal.srikanth@team-group.com | O17: =IFERROR(__xludf.DUMMYFUNCTION("""COMPUTED_VALUE"""),"Yes") -> Yes | P17: =IFERROR(__xludf.DUMMYFUNCTION("""COMPUTED_VALUE"""),"Yes") -> Yes | Q17: =IFERROR(__xludf.DUMMYFUNCTION("""COMPUTED_VALUE"""),"Yes") -> Yes | R17: =IFERROR(__xludf.DUMMYFUNCTION("""COMPUTED_VALUE"""),"Yes") -> Yes | S17: =IFERROR(__xludf.DUMMYFUNCTION("""COMPUTED_VALUE"""),"Yes") -> Yes | T17: =IFERROR(__xludf.DUMMYFUNCTION("""COMPUTED_VALUE"""),"Yes") -> Yes | U17: =IFERROR(__xludf.DUMMYFUNCTION("""COMPUTED_VALUE"""),"Yes") -> Yes | V17: =IFERROR(__xludf.DUMMYFUNCTION("""COMPUTED_VALUE"""),"Yes") -> Yes | ... AI17: =IFERROR(__xludf.DUMMYFUNCTION("""COMPUTED_VALUE"""),"Yes") -> Yes
A18: =IFERROR(__xludf.DUMMYFUNCTION("""COMPUTED_VALUE"""),2.50806004E8) -> 250806004 | B18: =IFERROR(__xludf.DUMMYFUNCTION("""COMPUTED_VALUE"""),"John") -> John | C18: =IFERROR(__xludf.DUMMYFUNCTION("""COMPUTED_VALUE"""),"JD") -> JD | D18: =IFERROR(__xludf.DUMMYFUNCTION("""COMPUTED_VALUE"""),"Doe") -> Doe | E18: =IFERROR(__xludf.DUMMYFUNCTION("""COMPUTED_VALUE"""),"JD") -> JD | F18: =IFERROR(__xludf.DUMMYFUNCTION("""COMPUTED_VALUE"""),"VP") -> VP | G18: =IFERROR(__xludf.DUMMYFUNCTION("""COMPUTED_VALUE"""),"email") -> email | I18: =IFERROR(__xludf.DUMMYFUNCTION("""COMPUTED_VALUE"""),"Hourly") -> Hourly | J18: =IFERROR(__xludf.DUMMYFUNCTION("""COMPUTED_VALUE"""),45889.0) -> 45889 | K18: =IFERROR(__xludf.DUMMYFUNCTION("""COMPUTED_VALUE"""),"GM Oshawa Assembly") -> GM Oshawa Assembly | L18: =IFERROR(__xludf.DUMMYFUNCTION("""COMPUTED_VALUE"""),135.0) -> 135 | M18: =IFERROR(__xludf.DUMMYFUNCTION("""COMPUTED_VALUE"""),"Jane Doe") -> Jane Doe | N18: =IFERROR(__xludf.DUMMYFUNCTION("""COMPUTED_VALUE"""),"Vishal.srikanth@team-group.com") -> Vishal.srikanth@team-group.com | O18: =IFERROR(__xludf.DUMMYFUNCTION("""COMPUTED_VALUE"""),"Yes") -> Yes | P18: =IFERROR(__xludf.DUMMYFUNCTION("""COMPUTED_VALUE"""),"No") -> No | Q18: =IFERROR(__xludf.DUMMYFUNCTION("""COMPUTED_VALUE"""),"No") -> No | R18: =IFERROR(__xludf.DUMMYFUNCTION("""COMPUTED_VALUE"""),"No") -> No | S18: =IFERROR(__xludf.DUMMYFUNCTION("""COMPUTED_VALUE"""),"Yes") -> Yes | T18: =IFERROR(__xludf.DUMMYFUNCTION("""COMPUTED_VALUE"""),"No") -> No | U18: =IFERROR(__xludf.DUMMYFUNCTION("""COMPUTED_VALUE"""),"Yes") -> Yes | V18: =IFERROR(__xludf.DUMMYFUNCTION("""COMPUTED_VALUE"""),"No") -> No | W18: =IFERROR(__xludf.DUMMYFUNCTION("""COMPUTED_VALUE"""),"Yes") -> Yes | X18: =IFERROR(__xludf.DUMMYFUNCTION("""COMPUTED_VALUE"""),"No") -> No | Y18: =IFERROR(__xludf.DUMMYFUNCTION("""COMPUTED_VALUE"""),"No") -> No | Z18: =IFERROR(__xludf.DUMMYFUNCTION("""COMPUTED_VALUE"""),"No") -> No | AA18: =IFERROR(__xludf.DUMMYFUNCTION("""COMPUTED_VALUE"""),"No") -> No | AB18: =IFERROR(__xludf.DUMMYFUNCTION("""COMPUTED_VALUE"""),"No") -> No | AC18: =IFERROR(__xludf.DUMMYFUNCTION("""COMPUTED_VALUE"""),"No") -> No | AD18: =IFERROR(__xludf.DUMMYFUNCTION("""COMPUTED_VALUE"""),"No") -> No | AE18: =IFERROR(__xludf.DUMMYFUNCTION("""COMPUTED_VALUE"""),"Yes") -> Yes | AF18: =IFERROR(__xludf.DUMMYFUNCTION("""COMPUTED_VALUE"""),"No") -> No | AG18: =IFERROR(__xludf.DUMMYFUNCTION("""COMPUTED_VALUE"""),"No") -> No | AH18: =IFERROR(__xludf.DUMMYFUNCTION("""COMPUTED_VALUE"""),"Yes") -> Yes | AI18: =IFERROR(__xludf.DUMMYFUNCTION("""COMPUTED_VALUE"""),"No") -> No
A19: =IFERROR(__xludf.DUMMYFUNCTION("""COMPUTED_VALUE"""),2.50807001E8) -> 250807001 | B19: =IFERROR(__xludf.DUMMYFUNCTION("""COMPUTED_VALUE"""),"John") -> John | C19: =IFERROR(__xludf.DUMMYFUNCTION("""COMPUTED_VALUE"""),"JD") -> JD | D19: =IFERROR(__xludf.DUMMYFUNCTION("""COMPUTED_VALUE"""),"Doe") -> Doe | E19: =IFERROR(__xludf.DUMMYFUNCTION("""COMPUTED_VALUE"""),"JD") -> JD | F19: =IFERROR(__xludf.DUMMYFUNCTION("""COMPUTED_VALUE"""),"VP") -> VP | G19: =IFERROR(__xludf.DUMMYFUNCTION("""COMPUTED_VALUE"""),"email") -> email | H19: =IFERROR(__xludf.DUMMYFUNCTION("""COMPUTED_VALUE"""),123.0) -> 123 | I19: =IFERROR(__xludf.DUMMYFUNCTION("""COMPUTED_VALUE"""),"Hourly") -> Hourly | J19: =IFERROR(__xludf.DUMMYFUNCTION("""COMPUTED_VALUE"""),45877.0) -> 45877 | K19: =IFERROR(__xludf.DUMMYFUNCTION("""COMPUTED_VALUE"""),"Decostar Industries") -> Decostar Industries | L19: =IFERROR(__xludf.DUMMYFUNCTION("""COMPUTED_VALUE"""),132.0) -> 132 | M19: =IFERROR(__xludf.DUMMYFUNCTION("""COMPUTED_VALUE"""),"Jane Doe") -> Jane Doe | N19: =IFERROR(__xludf.DUMMYFUNCTION("""COMPUTED_VALUE"""),"Vishal.srikanth@team-group.com") -> Vishal.srikanth@team-group.com | O19: =IFERROR(__xludf.DUMMYFUNCTION("""COMPUTED_VALUE"""),"Yes") -> Yes | P19: =IFERROR(__xludf.DUMMYFUNCTION("""COMPUTED_VALUE"""),"Yes") -> Yes | Q19: =IFERROR(__xludf.DUMMYFUNCTION("""COMPUTED_VALUE"""),"Yes") -> Yes | R19: =IFERROR(__xludf.DUMMYFUNCTION("""COMPUTED_VALUE"""),"Yes") -> Yes | S19: =IFERROR(__xludf.DUMMYFUNCTION("""COMPUTED_VALUE"""),"Yes") -> Yes | T19: =IFERROR(__xludf.DUMMYFUNCTION("""COMPUTED_VALUE"""),"Yes") -> Yes | U19: =IFERROR(__xludf.DUMMYFUNCTION("""COMPUTED_VALUE"""),"Yes") -> Yes | V19: =IFERROR(__xludf.DUMMYFUNCTION("""COMPUTED_VALUE"""),"Yes") -> Yes | ... AI19: =IFERROR(__xludf.DUMMYFUNCTION("""COMPUTED_VALUE"""),"Yes") -> Yes
A20: =IFERROR(__xludf.DUMMYFUNCTION("""COMPUTED_VALUE"""),2.50807002E8) -> 250807002 | B20: =IFERROR(__xludf.DUMMYFUNCTION("""COMPUTED_VALUE"""),"John") -> John | C20: =IFERROR(__xludf.DUMMYFUNCTION("""COMPUTED_VALUE"""),"JD") -> JD | D20: =IFERROR(__xludf.DUMMYFUNCTION("""COMPUTED_VALUE"""),"Doe") -> Doe | E20: =IFERROR(__xludf.DUMMYFUNCTION("""COMPUTED_VALUE"""),"JD") -> JD | F20: =IFERROR(__xludf.DUMMYFUNCTION("""COMPUTED_VALUE"""),"VP") -> VP | G20: =IFERROR(__xludf.DUMMYFUNCTION("""COMPUTED_VALUE"""),"email") -> email | H20: =IFERROR(__xludf.DUMMYFUNCTION("""COMPUTED_VALUE"""),123.0) -> 123 | I20: =IFERROR(__xludf.DUMMYFUNCTION("""COMPUTED_VALUE"""),"Salary") -> Salary | J20: =IFERROR(__xludf.DUMMYFUNCTION("""COMPUTED_VALUE"""),45881.0) -> 45881 | K20: =IFERROR(__xludf.DUMMYFUNCTION("""COMPUTED_VALUE"""),"BMW Spartanburg Assembly") -> BMW Spartanburg Assembly | L20: =IFERROR(__xludf.DUMMYFUNCTION("""COMPUTED_VALUE"""),120.0) -> 120 | M20: =IFERROR(__xludf.DUMMYFUNCTION("""COMPUTED_VALUE"""),"Jane Doe") -> Jane Doe | N20: =IFERROR(__xludf.DUMMYFUNCTION("""COMPUTED_VALUE"""),"Vishal.srikanth@team-group.com") -> Vishal.srikanth@team-group.com | O20: =IFERROR(__xludf.DUMMYFUNCTION("""COMPUTED_VALUE"""),"Yes") -> Yes | P20: =IFERROR(__xludf.DUMMYFUNCTION("""COMPUTED_VALUE"""),"Yes") -> Yes | Q20: =IFERROR(__xludf.DUMMYFUNCTION("""COMPUTED_VALUE"""),"Yes") -> Yes | R20: =IFERROR(__xludf.DUMMYFUNCTION("""COMPUTED_VALUE"""),"Yes") -> Yes | S20: =IFERROR(__xludf.DUMMYFUNCTION("""COMPUTED_VALUE"""),"Yes") -> Yes | T20: =IFERROR(__xludf.DUMMYFUNCTION("""COMPUTED_VALUE"""),"Yes") -> Yes | U20: =IFERROR(__xludf.DUMMYFUNCTION("""COMPUTED_VALUE"""),"Yes") -> Yes | V20: =IFERROR(__xludf.DUMMYFUNCTION("""COMPUTED_VALUE"""),"Yes") -> Yes | ... AI20: =IFERROR(__xludf.DUMMYFUNCTION("""COMPUTED_VALUE"""),"Yes") -> Yes
